<!DOCTYPE html>
<html lang="en">

<head>
  <meta charset="UTF-8">
  <meta name="viewport" content="width=device-width, initial-scale=1.0">
  <meta http-equiv="X-UA-Compatible" content="ie=edge">
  <title>Document</title>
</head>

<body>
  <script>
    (function () {
      // 如果await后面的异步操作出错，那么等同于async函数返回的 Promise 对象被reject。
      async function f() {
        await new Promise(function (resolve, reject) {
          throw new Error('出错了');
        });
      }

      f()
        .then(v => console.log(v))
        .catch(e => console.log(e))
      // Error：出错了
      // 上面代码中，async函数f执行后，await后面的 Promise 对象会抛出一个错误对象，导致catch方法的回调函数被调用，它的参数就是抛出的错误对象。具体的执行机制，可以参考后文的“async 函数的实现原理”。
    })();

    console.log('------------------------');

    (function () {
      // 防止出错的方法，也是将其放在try...catch代码块之中。
      async function f() {
        try {
          await new Promise(function (resolve, reject) {
            throw new Error('出错了');
          });
        } catch (e) {}
        return await ('hello world');
      }
    })();

    console.log('------------------------');

    (function () {
      // 如果有多个await命令，可以统一放在try...catch结构中。

      async function main() {
        try {
          const val1 = await firstStep();
          const val2 = await secondStep(val1);
          const val3 = await thirdStep(val1, val2);

          console.log('Final: ', val3);
        } catch (err) {
          console.error(err);
        }
      }
    })();

    console.log('------------------------');

    (function () {
      // 下面的例子使用try...catch结构，实现多次重复尝试。

      const superagent = require('superagent');
      const NUM_RETRIES = 3;

      async function test() {
        let i;
        for (i = 0; i < NUM_RETRIES; ++i) {
          try {
            await superagent.get('http://google.com/this-throws-an-error');
            break;
          } catch (err) {}
        }
        console.log(i); // 3
      }

      test();
      // 上面代码中，如果await操作成功，就会使用break语句退出循环；如果失败，会被catch语句捕捉，然后进入下一轮循环。
    })();
  </script>
</body>

</html>