<!DOCTYPE html>
<html lang="en">

<head>
  <meta charset="UTF-8">
  <meta name="viewport" content="width=device-width, initial-scale=1.0">
  <meta http-equiv="X-UA-Compatible" content="ie=edge">
  <title>Document</title>
</head>

<body>
  <script>
    // await 命令
    // 正常情况下，await命令后面是一个 Promise 对象。如果不是，会被转成一个立即resolve的 Promise 对象。
    (function () {

      async function f() {
        return await 123;
      }

      f().then(v => console.log(v))
      // 123
      // 上面代码中，await命令的参数是数值123，它被转成 Promise 对象，并立即resolve。
    })();
    (function () {

      // await命令后面的 Promise 对象如果变为reject状态，则reject的参数会被catch方法的回调函数接收到。

      async function f() {
        await Promise.reject('出错了');
      }

      f()
        .then(v => console.log(v))
        .catch(e => console.log(e))
      // 出错了
      // 注意，上面代码中，await语句前面没有return，但是reject方法的参数依然传入了catch方法的回调函数。这里如果在await前面加上return，效果是一样的。
    })();
    (function () {
      // 只要一个await语句后面的 Promise 变为reject，那么整个async函数都会中断执行。

      async function f() {
        await Promise.reject('出错了');
        await Promise.resolve('hello world'); // 不会执行
      }
      // 上面代码中，第二个await语句是不会执行的，因为第一个await语句状态变成了reject。
    })();
    (function () {
      // 有时，我们希望即使前一个异步操作失败，也不要中断后面的异步操作。这时可以将第一个await放在try...catch结构里面，这样不管这个异步操作是否成功，第二个await都会执行。

      async function f() {
        try {
          await Promise.reject('出错了');
        } catch (e) {}
        return await Promise.resolve('hello world');
      }

      f()
        .then(v => console.log(v))
      // hello world
    })();
    (function () {
      // 另一种方法是await后面的 Promise 对象再跟一个catch方法，处理前面可能出现的错误。

      async function f() {
        await Promise.reject('出错了')
          .catch(e => console.log(e));
        return await Promise.resolve('hello world');
      }

      f()
        .then(v => console.log(v))
      // 出错了
      // hello world
    })();
  </script>
</body>

</html>